Traceback (most recent call last):
  File "/Users/russod01/Desktop/GroupProject/webDevGroupCoursework/manage.py", line 22, in <module>
    main()
  File "/Users/russod01/Desktop/GroupProject/webDevGroupCoursework/manage.py", line 18, in main
    execute_from_command_line(sys.argv)
  File "/Library/Frameworks/Python.framework/Versions/3.10/lib/python3.10/site-packages/django/core/management/__init__.py", line 446, in execute_from_command_line
    utility.execute()
  File "/Library/Frameworks/Python.framework/Versions/3.10/lib/python3.10/site-packages/django/core/management/__init__.py", line 440, in execute
    self.fetch_command(subcommand).run_from_argv(self.argv)
  File "/Library/Frameworks/Python.framework/Versions/3.10/lib/python3.10/site-packages/django/core/management/base.py", line 402, in run_from_argv
    self.execute(*args, **cmd_options)
  File "/Library/Frameworks/Python.framework/Versions/3.10/lib/python3.10/site-packages/django/core/management/base.py", line 443, in execute
    self.check()
  File "/Library/Frameworks/Python.framework/Versions/3.10/lib/python3.10/site-packages/django/core/management/base.py", line 475, in check
    all_issues = checks.run_checks(
  File "/Library/Frameworks/Python.framework/Versions/3.10/lib/python3.10/site-packages/django/core/checks/registry.py", line 88, in run_checks
    new_errors = check(app_configs=app_configs, databases=databases)
  File "/Library/Frameworks/Python.framework/Versions/3.10/lib/python3.10/site-packages/django/core/checks/urls.py", line 14, in check_url_config
    return check_resolver(resolver)
  File "/Library/Frameworks/Python.framework/Versions/3.10/lib/python3.10/site-packages/django/core/checks/urls.py", line 24, in check_resolver
    return check_method()
  File "/Library/Frameworks/Python.framework/Versions/3.10/lib/python3.10/site-packages/django/urls/resolvers.py", line 494, in check
    for pattern in self.url_patterns:
  File "/Library/Frameworks/Python.framework/Versions/3.10/lib/python3.10/site-packages/django/utils/functional.py", line 57, in __get__
    res = instance.__dict__[self.name] = self.func(instance)
  File "/Library/Frameworks/Python.framework/Versions/3.10/lib/python3.10/site-packages/django/urls/resolvers.py", line 715, in url_patterns
    patterns = getattr(self.urlconf_module, "urlpatterns", self.urlconf_module)
  File "/Library/Frameworks/Python.framework/Versions/3.10/lib/python3.10/site-packages/django/utils/functional.py", line 57, in __get__
    res = instance.__dict__[self.name] = self.func(instance)
  File "/Library/Frameworks/Python.framework/Versions/3.10/lib/python3.10/site-packages/django/urls/resolvers.py", line 708, in urlconf_module
    return import_module(self.urlconf_name)
  File "/Library/Frameworks/Python.framework/Versions/3.10/lib/python3.10/importlib/__init__.py", line 126, in import_module
    return _bootstrap._gcd_import(name[level:], package, level)
  File "<frozen importlib._bootstrap>", line 1050, in _gcd_import
  File "<frozen importlib._bootstrap>", line 1027, in _find_and_load
  File "<frozen importlib._bootstrap>", line 1006, in _find_and_load_unlocked
  File "<frozen importlib._bootstrap>", line 688, in _load_unlocked
  File "<frozen importlib._bootstrap_external>", line 883, in exec_module
  File "<frozen importlib._bootstrap>", line 241, in _call_with_frames_removed
  File "/Users/russod01/Desktop/GroupProject/webDevGroupCoursework/project/urls.py", line 20, in <module>
    from welcome.views import index, health
  File "/Users/russod01/Desktop/GroupProject/webDevGroupCoursework/welcome/views.py", line 9, in <module>
    from .forms import UserRegistration, UserLogin
  File "/Users/russod01/Desktop/GroupProject/webDevGroupCoursework/welcome/forms.py", line 4, in <module>
    class UserRegistration(forms.Form):
  File "/Users/russod01/Desktop/GroupProject/webDevGroupCoursework/welcome/forms.py", line 5, in UserRegistration
    name = forms.CharField(label="name", required=True, attrs={'placeholder': 'Name', 'class': 'form-control mb-3'})
  File "/Library/Frameworks/Python.framework/Versions/3.10/lib/python3.10/site-packages/django/forms/fields.py", line 267, in __init__
    super().__init__(**kwargs)
TypeError: Field.__init__() got an unexpected keyword argument 'attrs'
Traceback (most recent call last):
  File "/Users/russod01/Desktop/GroupProject/webDevGroupCoursework/manage.py", line 22, in <module>
    main()
  File "/Users/russod01/Desktop/GroupProject/webDevGroupCoursework/manage.py", line 18, in main
    execute_from_command_line(sys.argv)
  File "/Library/Frameworks/Python.framework/Versions/3.10/lib/python3.10/site-packages/django/core/management/__init__.py", line 446, in execute_from_command_line
    utility.execute()
  File "/Library/Frameworks/Python.framework/Versions/3.10/lib/python3.10/site-packages/django/core/management/__init__.py", line 440, in execute
    self.fetch_command(subcommand).run_from_argv(self.argv)
  File "/Library/Frameworks/Python.framework/Versions/3.10/lib/python3.10/site-packages/django/core/management/base.py", line 402, in run_from_argv
    self.execute(*args, **cmd_options)
  File "/Library/Frameworks/Python.framework/Versions/3.10/lib/python3.10/site-packages/django/core/management/base.py", line 443, in execute
    self.check()
  File "/Library/Frameworks/Python.framework/Versions/3.10/lib/python3.10/site-packages/django/core/management/base.py", line 475, in check
    all_issues = checks.run_checks(
  File "/Library/Frameworks/Python.framework/Versions/3.10/lib/python3.10/site-packages/django/core/checks/registry.py", line 88, in run_checks
    new_errors = check(app_configs=app_configs, databases=databases)
  File "/Library/Frameworks/Python.framework/Versions/3.10/lib/python3.10/site-packages/django/core/checks/urls.py", line 14, in check_url_config
    return check_resolver(resolver)
  File "/Library/Frameworks/Python.framework/Versions/3.10/lib/python3.10/site-packages/django/core/checks/urls.py", line 24, in check_resolver
    return check_method()
  File "/Library/Frameworks/Python.framework/Versions/3.10/lib/python3.10/site-packages/django/urls/resolvers.py", line 494, in check
    for pattern in self.url_patterns:
  File "/Library/Frameworks/Python.framework/Versions/3.10/lib/python3.10/site-packages/django/utils/functional.py", line 57, in __get__
    res = instance.__dict__[self.name] = self.func(instance)
  File "/Library/Frameworks/Python.framework/Versions/3.10/lib/python3.10/site-packages/django/urls/resolvers.py", line 715, in url_patterns
    patterns = getattr(self.urlconf_module, "urlpatterns", self.urlconf_module)
  File "/Library/Frameworks/Python.framework/Versions/3.10/lib/python3.10/site-packages/django/utils/functional.py", line 57, in __get__
    res = instance.__dict__[self.name] = self.func(instance)
  File "/Library/Frameworks/Python.framework/Versions/3.10/lib/python3.10/site-packages/django/urls/resolvers.py", line 708, in urlconf_module
    return import_module(self.urlconf_name)
  File "/Library/Frameworks/Python.framework/Versions/3.10/lib/python3.10/importlib/__init__.py", line 126, in import_module
    return _bootstrap._gcd_import(name[level:], package, level)
  File "<frozen importlib._bootstrap>", line 1050, in _gcd_import
  File "<frozen importlib._bootstrap>", line 1027, in _find_and_load
  File "<frozen importlib._bootstrap>", line 1006, in _find_and_load_unlocked
  File "<frozen importlib._bootstrap>", line 688, in _load_unlocked
  File "<frozen importlib._bootstrap_external>", line 883, in exec_module
  File "<frozen importlib._bootstrap>", line 241, in _call_with_frames_removed
  File "/Users/russod01/Desktop/GroupProject/webDevGroupCoursework/project/urls.py", line 20, in <module>
    from welcome.views import index, health
  File "/Users/russod01/Desktop/GroupProject/webDevGroupCoursework/welcome/views.py", line 9, in <module>
    from .forms import UserRegistration, UserLogin
  File "/Users/russod01/Desktop/GroupProject/webDevGroupCoursework/welcome/forms.py", line 4, in <module>
    class UserRegistration(forms.Form):
  File "/Users/russod01/Desktop/GroupProject/webDevGroupCoursework/welcome/forms.py", line 5, in UserRegistration
    name = forms.CharField(label="name", required=True, attrs={'placeholder': 'Name', 'class': 'form-control mb-3'})
  File "/Library/Frameworks/Python.framework/Versions/3.10/lib/python3.10/site-packages/django/forms/fields.py", line 267, in __init__
    super().__init__(**kwargs)
TypeError: Field.__init__() got an unexpected keyword argument 'attrs'
Traceback (most recent call last):
  File "/Users/russod01/Desktop/GroupProject/webDevGroupCoursework/manage.py", line 22, in <module>
    main()
  File "/Users/russod01/Desktop/GroupProject/webDevGroupCoursework/manage.py", line 18, in main
    execute_from_command_line(sys.argv)
  File "/Library/Frameworks/Python.framework/Versions/3.10/lib/python3.10/site-packages/django/core/management/__init__.py", line 446, in execute_from_command_line
    utility.execute()
  File "/Library/Frameworks/Python.framework/Versions/3.10/lib/python3.10/site-packages/django/core/management/__init__.py", line 440, in execute
    self.fetch_command(subcommand).run_from_argv(self.argv)
  File "/Library/Frameworks/Python.framework/Versions/3.10/lib/python3.10/site-packages/django/core/management/base.py", line 402, in run_from_argv
    self.execute(*args, **cmd_options)
  File "/Library/Frameworks/Python.framework/Versions/3.10/lib/python3.10/site-packages/django/core/management/base.py", line 443, in execute
    self.check()
  File "/Library/Frameworks/Python.framework/Versions/3.10/lib/python3.10/site-packages/django/core/management/base.py", line 475, in check
    all_issues = checks.run_checks(
  File "/Library/Frameworks/Python.framework/Versions/3.10/lib/python3.10/site-packages/django/core/checks/registry.py", line 88, in run_checks
    new_errors = check(app_configs=app_configs, databases=databases)
  File "/Library/Frameworks/Python.framework/Versions/3.10/lib/python3.10/site-packages/django/core/checks/urls.py", line 14, in check_url_config
    return check_resolver(resolver)
  File "/Library/Frameworks/Python.framework/Versions/3.10/lib/python3.10/site-packages/django/core/checks/urls.py", line 24, in check_resolver
    return check_method()
  File "/Library/Frameworks/Python.framework/Versions/3.10/lib/python3.10/site-packages/django/urls/resolvers.py", line 494, in check
    for pattern in self.url_patterns:
  File "/Library/Frameworks/Python.framework/Versions/3.10/lib/python3.10/site-packages/django/utils/functional.py", line 57, in __get__
    res = instance.__dict__[self.name] = self.func(instance)
  File "/Library/Frameworks/Python.framework/Versions/3.10/lib/python3.10/site-packages/django/urls/resolvers.py", line 715, in url_patterns
    patterns = getattr(self.urlconf_module, "urlpatterns", self.urlconf_module)
  File "/Library/Frameworks/Python.framework/Versions/3.10/lib/python3.10/site-packages/django/utils/functional.py", line 57, in __get__
    res = instance.__dict__[self.name] = self.func(instance)
  File "/Library/Frameworks/Python.framework/Versions/3.10/lib/python3.10/site-packages/django/urls/resolvers.py", line 708, in urlconf_module
    return import_module(self.urlconf_name)
  File "/Library/Frameworks/Python.framework/Versions/3.10/lib/python3.10/importlib/__init__.py", line 126, in import_module
    return _bootstrap._gcd_import(name[level:], package, level)
  File "<frozen importlib._bootstrap>", line 1050, in _gcd_import
  File "<frozen importlib._bootstrap>", line 1027, in _find_and_load
  File "<frozen importlib._bootstrap>", line 1006, in _find_and_load_unlocked
  File "<frozen importlib._bootstrap>", line 688, in _load_unlocked
  File "<frozen importlib._bootstrap_external>", line 883, in exec_module
  File "<frozen importlib._bootstrap>", line 241, in _call_with_frames_removed
  File "/Users/russod01/Desktop/GroupProject/webDevGroupCoursework/project/urls.py", line 24, in <module>
    path('bidder/', include('welcome.urls')),
  File "/Library/Frameworks/Python.framework/Versions/3.10/lib/python3.10/site-packages/django/urls/conf.py", line 38, in include
    urlconf_module = import_module(urlconf_module)
  File "/Library/Frameworks/Python.framework/Versions/3.10/lib/python3.10/importlib/__init__.py", line 126, in import_module
    return _bootstrap._gcd_import(name[level:], package, level)
  File "<frozen importlib._bootstrap>", line 1050, in _gcd_import
  File "<frozen importlib._bootstrap>", line 1027, in _find_and_load
  File "<frozen importlib._bootstrap>", line 1006, in _find_and_load_unlocked
  File "<frozen importlib._bootstrap>", line 688, in _load_unlocked
  File "<frozen importlib._bootstrap_external>", line 883, in exec_module
  File "<frozen importlib._bootstrap>", line 241, in _call_with_frames_removed
  File "/Users/russod01/Desktop/GroupProject/webDevGroupCoursework/welcome/urls.py", line 23, in <module>
    re_path(r'^.*', spa_view, name='vue SPA'),
NameError: name 'spa_view' is not defined
Traceback (most recent call last):
  File "/Users/russod01/Desktop/GroupProject/webDevGroupCoursework/manage.py", line 22, in <module>
    main()
  File "/Users/russod01/Desktop/GroupProject/webDevGroupCoursework/manage.py", line 18, in main
    execute_from_command_line(sys.argv)
  File "/Library/Frameworks/Python.framework/Versions/3.10/lib/python3.10/site-packages/django/core/management/__init__.py", line 446, in execute_from_command_line
    utility.execute()
  File "/Library/Frameworks/Python.framework/Versions/3.10/lib/python3.10/site-packages/django/core/management/__init__.py", line 440, in execute
    self.fetch_command(subcommand).run_from_argv(self.argv)
  File "/Library/Frameworks/Python.framework/Versions/3.10/lib/python3.10/site-packages/django/core/management/base.py", line 402, in run_from_argv
    self.execute(*args, **cmd_options)
  File "/Library/Frameworks/Python.framework/Versions/3.10/lib/python3.10/site-packages/django/core/management/base.py", line 443, in execute
    self.check()
  File "/Library/Frameworks/Python.framework/Versions/3.10/lib/python3.10/site-packages/django/core/management/base.py", line 475, in check
    all_issues = checks.run_checks(
  File "/Library/Frameworks/Python.framework/Versions/3.10/lib/python3.10/site-packages/django/core/checks/registry.py", line 88, in run_checks
    new_errors = check(app_configs=app_configs, databases=databases)
  File "/Library/Frameworks/Python.framework/Versions/3.10/lib/python3.10/site-packages/django/core/checks/urls.py", line 14, in check_url_config
    return check_resolver(resolver)
  File "/Library/Frameworks/Python.framework/Versions/3.10/lib/python3.10/site-packages/django/core/checks/urls.py", line 24, in check_resolver
    return check_method()
  File "/Library/Frameworks/Python.framework/Versions/3.10/lib/python3.10/site-packages/django/urls/resolvers.py", line 494, in check
    for pattern in self.url_patterns:
  File "/Library/Frameworks/Python.framework/Versions/3.10/lib/python3.10/site-packages/django/utils/functional.py", line 57, in __get__
    res = instance.__dict__[self.name] = self.func(instance)
  File "/Library/Frameworks/Python.framework/Versions/3.10/lib/python3.10/site-packages/django/urls/resolvers.py", line 715, in url_patterns
    patterns = getattr(self.urlconf_module, "urlpatterns", self.urlconf_module)
  File "/Library/Frameworks/Python.framework/Versions/3.10/lib/python3.10/site-packages/django/utils/functional.py", line 57, in __get__
    res = instance.__dict__[self.name] = self.func(instance)
  File "/Library/Frameworks/Python.framework/Versions/3.10/lib/python3.10/site-packages/django/urls/resolvers.py", line 708, in urlconf_module
    return import_module(self.urlconf_name)
  File "/Library/Frameworks/Python.framework/Versions/3.10/lib/python3.10/importlib/__init__.py", line 126, in import_module
    return _bootstrap._gcd_import(name[level:], package, level)
  File "<frozen importlib._bootstrap>", line 1050, in _gcd_import
  File "<frozen importlib._bootstrap>", line 1027, in _find_and_load
  File "<frozen importlib._bootstrap>", line 1006, in _find_and_load_unlocked
  File "<frozen importlib._bootstrap>", line 688, in _load_unlocked
  File "<frozen importlib._bootstrap_external>", line 883, in exec_module
  File "<frozen importlib._bootstrap>", line 241, in _call_with_frames_removed
  File "/Users/russod01/Desktop/GroupProject/webDevGroupCoursework/project/urls.py", line 24, in <module>
    path('bidder/', include('welcome.urls')),
  File "/Library/Frameworks/Python.framework/Versions/3.10/lib/python3.10/site-packages/django/urls/conf.py", line 38, in include
    urlconf_module = import_module(urlconf_module)
  File "/Library/Frameworks/Python.framework/Versions/3.10/lib/python3.10/importlib/__init__.py", line 126, in import_module
    return _bootstrap._gcd_import(name[level:], package, level)
  File "<frozen importlib._bootstrap>", line 1050, in _gcd_import
  File "<frozen importlib._bootstrap>", line 1027, in _find_and_load
  File "<frozen importlib._bootstrap>", line 1006, in _find_and_load_unlocked
  File "<frozen importlib._bootstrap>", line 688, in _load_unlocked
  File "<frozen importlib._bootstrap_external>", line 883, in exec_module
  File "<frozen importlib._bootstrap>", line 241, in _call_with_frames_removed
  File "/Users/russod01/Desktop/GroupProject/webDevGroupCoursework/welcome/urls.py", line 23, in <module>
    re_path(r'^.*', spa_view, name='vue SPA'),
NameError: name 'spa_view' is not defined
Traceback (most recent call last):
  File "/Users/russod01/Desktop/GroupProject/webDevGroupCoursework/manage.py", line 22, in <module>
    main()
  File "/Users/russod01/Desktop/GroupProject/webDevGroupCoursework/manage.py", line 18, in main
    execute_from_command_line(sys.argv)
  File "/Library/Frameworks/Python.framework/Versions/3.10/lib/python3.10/site-packages/django/core/management/__init__.py", line 446, in execute_from_command_line
    utility.execute()
  File "/Library/Frameworks/Python.framework/Versions/3.10/lib/python3.10/site-packages/django/core/management/__init__.py", line 440, in execute
    self.fetch_command(subcommand).run_from_argv(self.argv)
  File "/Library/Frameworks/Python.framework/Versions/3.10/lib/python3.10/site-packages/django/core/management/base.py", line 402, in run_from_argv
    self.execute(*args, **cmd_options)
  File "/Library/Frameworks/Python.framework/Versions/3.10/lib/python3.10/site-packages/django/core/management/base.py", line 443, in execute
    self.check()
  File "/Library/Frameworks/Python.framework/Versions/3.10/lib/python3.10/site-packages/django/core/management/base.py", line 475, in check
    all_issues = checks.run_checks(
  File "/Library/Frameworks/Python.framework/Versions/3.10/lib/python3.10/site-packages/django/core/checks/registry.py", line 88, in run_checks
    new_errors = check(app_configs=app_configs, databases=databases)
  File "/Library/Frameworks/Python.framework/Versions/3.10/lib/python3.10/site-packages/django/core/checks/urls.py", line 14, in check_url_config
    return check_resolver(resolver)
  File "/Library/Frameworks/Python.framework/Versions/3.10/lib/python3.10/site-packages/django/core/checks/urls.py", line 24, in check_resolver
    return check_method()
  File "/Library/Frameworks/Python.framework/Versions/3.10/lib/python3.10/site-packages/django/urls/resolvers.py", line 494, in check
    for pattern in self.url_patterns:
  File "/Library/Frameworks/Python.framework/Versions/3.10/lib/python3.10/site-packages/django/utils/functional.py", line 57, in __get__
    res = instance.__dict__[self.name] = self.func(instance)
  File "/Library/Frameworks/Python.framework/Versions/3.10/lib/python3.10/site-packages/django/urls/resolvers.py", line 715, in url_patterns
    patterns = getattr(self.urlconf_module, "urlpatterns", self.urlconf_module)
  File "/Library/Frameworks/Python.framework/Versions/3.10/lib/python3.10/site-packages/django/utils/functional.py", line 57, in __get__
    res = instance.__dict__[self.name] = self.func(instance)
  File "/Library/Frameworks/Python.framework/Versions/3.10/lib/python3.10/site-packages/django/urls/resolvers.py", line 708, in urlconf_module
    return import_module(self.urlconf_name)
  File "/Library/Frameworks/Python.framework/Versions/3.10/lib/python3.10/importlib/__init__.py", line 126, in import_module
    return _bootstrap._gcd_import(name[level:], package, level)
  File "<frozen importlib._bootstrap>", line 1050, in _gcd_import
  File "<frozen importlib._bootstrap>", line 1027, in _find_and_load
  File "<frozen importlib._bootstrap>", line 1006, in _find_and_load_unlocked
  File "<frozen importlib._bootstrap>", line 688, in _load_unlocked
  File "<frozen importlib._bootstrap_external>", line 883, in exec_module
  File "<frozen importlib._bootstrap>", line 241, in _call_with_frames_removed
  File "/Users/russod01/Desktop/GroupProject/webDevGroupCoursework/project/urls.py", line 24, in <module>
    path('bidder/', include('welcome.urls')),
  File "/Library/Frameworks/Python.framework/Versions/3.10/lib/python3.10/site-packages/django/urls/conf.py", line 38, in include
    urlconf_module = import_module(urlconf_module)
  File "/Library/Frameworks/Python.framework/Versions/3.10/lib/python3.10/importlib/__init__.py", line 126, in import_module
    return _bootstrap._gcd_import(name[level:], package, level)
  File "<frozen importlib._bootstrap>", line 1050, in _gcd_import
  File "<frozen importlib._bootstrap>", line 1027, in _find_and_load
  File "<frozen importlib._bootstrap>", line 1006, in _find_and_load_unlocked
  File "<frozen importlib._bootstrap>", line 688, in _load_unlocked
  File "<frozen importlib._bootstrap_external>", line 883, in exec_module
  File "<frozen importlib._bootstrap>", line 241, in _call_with_frames_removed
  File "/Users/russod01/Desktop/GroupProject/webDevGroupCoursework/welcome/urls.py", line 23, in <module>
    re_path(r'^.*', spa_view, name='vue SPA'),
NameError: name 'spa_view' is not defined
Traceback (most recent call last):
  File "/Users/russod01/Desktop/GroupProject/webDevGroupCoursework/manage.py", line 22, in <module>
    main()
  File "/Users/russod01/Desktop/GroupProject/webDevGroupCoursework/manage.py", line 18, in main
    execute_from_command_line(sys.argv)
  File "/Library/Frameworks/Python.framework/Versions/3.10/lib/python3.10/site-packages/django/core/management/__init__.py", line 446, in execute_from_command_line
    utility.execute()
  File "/Library/Frameworks/Python.framework/Versions/3.10/lib/python3.10/site-packages/django/core/management/__init__.py", line 440, in execute
    self.fetch_command(subcommand).run_from_argv(self.argv)
  File "/Library/Frameworks/Python.framework/Versions/3.10/lib/python3.10/site-packages/django/core/management/base.py", line 402, in run_from_argv
    self.execute(*args, **cmd_options)
  File "/Library/Frameworks/Python.framework/Versions/3.10/lib/python3.10/site-packages/django/core/management/base.py", line 443, in execute
    self.check()
  File "/Library/Frameworks/Python.framework/Versions/3.10/lib/python3.10/site-packages/django/core/management/base.py", line 475, in check
    all_issues = checks.run_checks(
  File "/Library/Frameworks/Python.framework/Versions/3.10/lib/python3.10/site-packages/django/core/checks/registry.py", line 88, in run_checks
    new_errors = check(app_configs=app_configs, databases=databases)
  File "/Library/Frameworks/Python.framework/Versions/3.10/lib/python3.10/site-packages/django/core/checks/urls.py", line 14, in check_url_config
    return check_resolver(resolver)
  File "/Library/Frameworks/Python.framework/Versions/3.10/lib/python3.10/site-packages/django/core/checks/urls.py", line 24, in check_resolver
    return check_method()
  File "/Library/Frameworks/Python.framework/Versions/3.10/lib/python3.10/site-packages/django/urls/resolvers.py", line 494, in check
    for pattern in self.url_patterns:
  File "/Library/Frameworks/Python.framework/Versions/3.10/lib/python3.10/site-packages/django/utils/functional.py", line 57, in __get__
    res = instance.__dict__[self.name] = self.func(instance)
  File "/Library/Frameworks/Python.framework/Versions/3.10/lib/python3.10/site-packages/django/urls/resolvers.py", line 715, in url_patterns
    patterns = getattr(self.urlconf_module, "urlpatterns", self.urlconf_module)
  File "/Library/Frameworks/Python.framework/Versions/3.10/lib/python3.10/site-packages/django/utils/functional.py", line 57, in __get__
    res = instance.__dict__[self.name] = self.func(instance)
  File "/Library/Frameworks/Python.framework/Versions/3.10/lib/python3.10/site-packages/django/urls/resolvers.py", line 708, in urlconf_module
    return import_module(self.urlconf_name)
  File "/Library/Frameworks/Python.framework/Versions/3.10/lib/python3.10/importlib/__init__.py", line 126, in import_module
    return _bootstrap._gcd_import(name[level:], package, level)
  File "<frozen importlib._bootstrap>", line 1050, in _gcd_import
  File "<frozen importlib._bootstrap>", line 1027, in _find_and_load
  File "<frozen importlib._bootstrap>", line 1006, in _find_and_load_unlocked
  File "<frozen importlib._bootstrap>", line 688, in _load_unlocked
  File "<frozen importlib._bootstrap_external>", line 883, in exec_module
  File "<frozen importlib._bootstrap>", line 241, in _call_with_frames_removed
  File "/Users/russod01/Desktop/GroupProject/webDevGroupCoursework/project/urls.py", line 20, in <module>
    from welcome.views import index, health
  File "/Users/russod01/Desktop/GroupProject/webDevGroupCoursework/welcome/views.py", line 73
    if request.method == 'GET':
IndentationError: unexpected indent
Failed to complete cronjob at ('* * * * *', 'welcome.cron.send_emails', '>> /Users/russod01/Desktop/GroupProject/webDevGroupCoursework/welcome/log/debug7.log 2>&1 ')
Traceback (most recent call last):
  File "/Library/Frameworks/Python.framework/Versions/3.10/lib/python3.10/site-packages/django/db/backends/utils.py", line 89, in _execute
    return self.cursor.execute(sql, params)
  File "/Library/Frameworks/Python.framework/Versions/3.10/lib/python3.10/site-packages/django/db/backends/sqlite3/base.py", line 357, in execute
    return Database.Cursor.execute(self, query, params)
sqlite3.OperationalError: no such table: welcome_item

The above exception was the direct cause of the following exception:

Traceback (most recent call last):
  File "/Library/Frameworks/Python.framework/Versions/3.10/lib/python3.10/site-packages/django_crontab/crontab.py", line 145, in run_job
    func(*job_args, **job_kwargs)
  File "/Users/russod01/Desktop/GroupProject/webDevGroupCoursework/welcome/cron.py", line 11, in send_emails
    for item in items:
  File "/Library/Frameworks/Python.framework/Versions/3.10/lib/python3.10/site-packages/django/db/models/query.py", line 394, in __iter__
    self._fetch_all()
  File "/Library/Frameworks/Python.framework/Versions/3.10/lib/python3.10/site-packages/django/db/models/query.py", line 1866, in _fetch_all
    self._result_cache = list(self._iterable_class(self))
  File "/Library/Frameworks/Python.framework/Versions/3.10/lib/python3.10/site-packages/django/db/models/query.py", line 87, in __iter__
    results = compiler.execute_sql(
  File "/Library/Frameworks/Python.framework/Versions/3.10/lib/python3.10/site-packages/django/db/models/sql/compiler.py", line 1398, in execute_sql
    cursor.execute(sql, params)
  File "/Library/Frameworks/Python.framework/Versions/3.10/lib/python3.10/site-packages/django/db/backends/utils.py", line 103, in execute
    return super().execute(sql, params)
  File "/Library/Frameworks/Python.framework/Versions/3.10/lib/python3.10/site-packages/django/db/backends/utils.py", line 67, in execute
    return self._execute_with_wrappers(
  File "/Library/Frameworks/Python.framework/Versions/3.10/lib/python3.10/site-packages/django/db/backends/utils.py", line 80, in _execute_with_wrappers
    return executor(sql, params, many, context)
  File "/Library/Frameworks/Python.framework/Versions/3.10/lib/python3.10/site-packages/django/db/backends/utils.py", line 84, in _execute
    with self.db.wrap_database_errors:
  File "/Library/Frameworks/Python.framework/Versions/3.10/lib/python3.10/site-packages/django/db/utils.py", line 91, in __exit__
    raise dj_exc_value.with_traceback(traceback) from exc_value
  File "/Library/Frameworks/Python.framework/Versions/3.10/lib/python3.10/site-packages/django/db/backends/utils.py", line 89, in _execute
    return self.cursor.execute(sql, params)
  File "/Library/Frameworks/Python.framework/Versions/3.10/lib/python3.10/site-packages/django/db/backends/sqlite3/base.py", line 357, in execute
    return Database.Cursor.execute(self, query, params)
django.db.utils.OperationalError: no such table: welcome_item
